2025-10-16 10:13:12,809 - alphagenome_ui - INFO - setup_logging:245 - AlphaGenome UI logging initialized
2025-10-16 10:13:31,514 - alphagenome_ui - INFO - setup_logging:245 - AlphaGenome UI logging initialized
2025-10-16 10:27:45,144 - alphagenome_ui - INFO - setup_logging:245 - AlphaGenome UI logging initialized
2025-10-16 10:27:50,286 - alphagenome_ui - INFO - setup_logging:245 - AlphaGenome UI logging initialized
2025-10-16 10:27:50,311 - alphagenome_ui - INFO - initialize_model:99 - Initializing AlphaGenome model
2025-10-16 10:27:50,313 - alphagenome_ui - ERROR - initialize_model:174 - Unexpected error during model initialization: Chainlit context not found
2025-10-16 10:27:50,318 - alphagenome_ui - ERROR - handle_unexpected_error:133 - Unexpected error during model initialization: Traceback (most recent call last):
  File "/usr/local/python/3.12.1/lib/python3.12/site-packages/chainlit/context.py", line 107, in get_context
    return context_var.get()
           ^^^^^^^^^^^^^^^^^
LookupError: <ContextVar name='chainlit' at 0x7e248bf1ede0>

The above exception was the direct cause of the following exception:

Traceback (most recent call last):
  File "/workspaces/alphagenome/app.py", line 113, in initialize_model
    loading_msg = await cl.Message(content="ðŸ”„ Initializing AlphaGenome model...").send()
                        ^^^^^^^^^^^^^^^^^^^^^^^^^^^^^^^^^^^^^^^^^^^^^^^^^^^^^^^^^^
  File "/usr/local/python/3.12.1/lib/python3.12/site-packages/chainlit/message.py", line 261, in __init__
    super().__post_init__()
  File "/usr/local/python/3.12.1/lib/python3.12/site-packages/chainlit/message.py", line 50, in __post_init__
    self.thread_id = context.session.thread_id
                     ^^^^^^^^^^^^^^^
  File "/usr/local/python/3.12.1/lib/python3.12/site-packages/lazify.py", line 133, in __getattr__
    return getattr(self.value, name)
                   ^^^^^^^^^^
  File "/usr/local/python/3.12.1/lib/python3.12/site-packages/lazify.py", line 56, in value
    value = self._func(*self._args, **self._kwargs)
            ^^^^^^^^^^^^^^^^^^^^^^^^^^^^^^^^^^^^^^^
  File "/usr/local/python/3.12.1/lib/python3.12/site-packages/chainlit/context.py", line 109, in get_context
    raise ChainlitContextException from e
chainlit.context.ChainlitContextException: Chainlit context not found

2025-10-16 10:27:50,575 - alphagenome_ui - INFO - initialize_model:99 - Initializing AlphaGenome model
2025-10-16 10:27:50,575 - alphagenome_ui - WARNING - initialize_model:107 - API key validation failed: Invalid API key format. Google API keys should start with 'AIza'
2025-10-16 10:27:50,576 - alphagenome_ui - WARNING - handle_validation_error:103 - Validation error [api_key]: Invalid API key format. Google API keys should start with 'AIza' (input: invalid_ke......)
2025-10-16 10:27:50,577 - alphagenome_ui - ERROR - initialize_model:174 - Unexpected error during model initialization: Chainlit context not found
2025-10-16 10:27:50,578 - alphagenome_ui - ERROR - handle_unexpected_error:133 - Unexpected error during model initialization: Traceback (most recent call last):
  File "/usr/local/python/3.12.1/lib/python3.12/site-packages/chainlit/context.py", line 107, in get_context
    return context_var.get()
           ^^^^^^^^^^^^^^^^^
LookupError: <ContextVar name='chainlit' at 0x7e248bf1ede0>

The above exception was the direct cause of the following exception:

Traceback (most recent call last):
  File "/workspaces/alphagenome/app.py", line 109, in initialize_model
    await cl.Message(content=error_msg, author="System").send()
          ^^^^^^^^^^^^^^^^^^^^^^^^^^^^^^^^^^^^^^^^^^^^^^
  File "/usr/local/python/3.12.1/lib/python3.12/site-packages/chainlit/message.py", line 261, in __init__
    super().__post_init__()
  File "/usr/local/python/3.12.1/lib/python3.12/site-packages/chainlit/message.py", line 50, in __post_init__
    self.thread_id = context.session.thread_id
                     ^^^^^^^^^^^^^^^
  File "/usr/local/python/3.12.1/lib/python3.12/site-packages/lazify.py", line 133, in __getattr__
    return getattr(self.value, name)
                   ^^^^^^^^^^
  File "/usr/local/python/3.12.1/lib/python3.12/site-packages/lazify.py", line 56, in value
    value = self._func(*self._args, **self._kwargs)
            ^^^^^^^^^^^^^^^^^^^^^^^^^^^^^^^^^^^^^^^
  File "/usr/local/python/3.12.1/lib/python3.12/site-packages/chainlit/context.py", line 109, in get_context
    raise ChainlitContextException from e
chainlit.context.ChainlitContextException: Chainlit context not found

2025-10-16 10:27:50,641 - alphagenome_ui - INFO - initialize_model:99 - Initializing AlphaGenome model
2025-10-16 10:27:50,642 - alphagenome_ui - ERROR - initialize_model:174 - Unexpected error during model initialization: Chainlit context not found
2025-10-16 10:27:50,643 - alphagenome_ui - ERROR - handle_unexpected_error:133 - Unexpected error during model initialization: Traceback (most recent call last):
  File "/usr/local/python/3.12.1/lib/python3.12/site-packages/chainlit/context.py", line 107, in get_context
    return context_var.get()
           ^^^^^^^^^^^^^^^^^
LookupError: <ContextVar name='chainlit' at 0x7e248bf1ede0>

The above exception was the direct cause of the following exception:

Traceback (most recent call last):
  File "/workspaces/alphagenome/app.py", line 113, in initialize_model
    loading_msg = await cl.Message(content="ðŸ”„ Initializing AlphaGenome model...").send()
                        ^^^^^^^^^^^^^^^^^^^^^^^^^^^^^^^^^^^^^^^^^^^^^^^^^^^^^^^^^^
  File "/usr/local/python/3.12.1/lib/python3.12/site-packages/chainlit/message.py", line 261, in __init__
    super().__post_init__()
  File "/usr/local/python/3.12.1/lib/python3.12/site-packages/chainlit/message.py", line 50, in __post_init__
    self.thread_id = context.session.thread_id
                     ^^^^^^^^^^^^^^^
  File "/usr/local/python/3.12.1/lib/python3.12/site-packages/lazify.py", line 133, in __getattr__
    return getattr(self.value, name)
                   ^^^^^^^^^^
  File "/usr/local/python/3.12.1/lib/python3.12/site-packages/lazify.py", line 56, in value
    value = self._func(*self._args, **self._kwargs)
            ^^^^^^^^^^^^^^^^^^^^^^^^^^^^^^^^^^^^^^^
  File "/usr/local/python/3.12.1/lib/python3.12/site-packages/chainlit/context.py", line 109, in get_context
    raise ChainlitContextException from e
chainlit.context.ChainlitContextException: Chainlit context not found

2025-10-16 10:30:17,256 - alphagenome_ui - INFO - setup_logging:245 - AlphaGenome UI logging initialized
2025-10-16 10:55:54,888 - alphagenome_ui - INFO - setup_logging:245 - AlphaGenome UI logging initialized
2025-10-16 10:58:27,061 - alphagenome_ui - INFO - setup_logging:245 - AlphaGenome UI logging initialized
2025-10-16 10:59:01,107 - alphagenome_ui - INFO - start:49 - Starting new chat session
2025-10-16 10:59:01,110 - alphagenome_ui - ERROR - handle_unexpected_error:133 - Unexpected error during session initialization: Traceback (most recent call last):
  File "/workspaces/alphagenome/app.py", line 77, in start
    await MessageEnhancements.send_enhanced_message(
  File "/workspaces/alphagenome/ui_enhancements.py", line 334, in send_enhanced_message
    avatar_config = cl.Avatar(
                    ^^^^^^^^^
  File "/usr/local/python/3.12.1/lib/python3.12/site-packages/chainlit/utils.py", line 85, in __getattr__
    module_path = registry[name]
                  ~~~~~~~~^^^^^^
KeyError: 'Avatar'

2025-10-16 10:59:01,112 - alphagenome_ui - INFO - end_timer:175 - Performance [session_initialization]: 0.005s
2025-10-16 10:59:22,526 - alphagenome_ui - INFO - start:49 - Starting new chat session
2025-10-16 10:59:22,527 - alphagenome_ui - ERROR - handle_unexpected_error:133 - Unexpected error during session initialization: Traceback (most recent call last):
  File "/workspaces/alphagenome/app.py", line 77, in start
    await MessageEnhancements.send_enhanced_message(
  File "/workspaces/alphagenome/ui_enhancements.py", line 334, in send_enhanced_message
    avatar_config = cl.Avatar(
                    ^^^^^^^^^
  File "/usr/local/python/3.12.1/lib/python3.12/site-packages/chainlit/utils.py", line 85, in __getattr__
    module_path = registry[name]
                  ~~~~~~~~^^^^^^
KeyError: 'Avatar'

2025-10-16 10:59:22,529 - alphagenome_ui - INFO - end_timer:175 - Performance [session_initialization]: 0.002s
2025-10-16 11:00:00,264 - alphagenome_ui - INFO - start:49 - Starting new chat session
2025-10-16 11:00:00,265 - alphagenome_ui - ERROR - handle_unexpected_error:133 - Unexpected error during session initialization: Traceback (most recent call last):
  File "/workspaces/alphagenome/app.py", line 77, in start
    await MessageEnhancements.send_enhanced_message(
  File "/workspaces/alphagenome/ui_enhancements.py", line 334, in send_enhanced_message
    avatar_config = cl.Avatar(
                    ^^^^^^^^^
  File "/usr/local/python/3.12.1/lib/python3.12/site-packages/chainlit/utils.py", line 85, in __getattr__
    module_path = registry[name]
                  ~~~~~~~~^^^^^^
KeyError: 'Avatar'

2025-10-16 11:00:00,268 - alphagenome_ui - INFO - end_timer:175 - Performance [session_initialization]: 0.003s
2025-10-16 11:00:20,530 - alphagenome_ui - INFO - start:49 - Starting new chat session
2025-10-16 11:00:20,531 - alphagenome_ui - ERROR - handle_unexpected_error:133 - Unexpected error during session initialization: Traceback (most recent call last):
  File "/workspaces/alphagenome/app.py", line 77, in start
    await MessageEnhancements.send_enhanced_message(
  File "/workspaces/alphagenome/ui_enhancements.py", line 334, in send_enhanced_message
    avatar_config = cl.Avatar(
                    ^^^^^^^^^
  File "/usr/local/python/3.12.1/lib/python3.12/site-packages/chainlit/utils.py", line 85, in __getattr__
    module_path = registry[name]
                  ~~~~~~~~^^^^^^
KeyError: 'Avatar'

2025-10-16 11:00:20,532 - alphagenome_ui - INFO - end_timer:175 - Performance [session_initialization]: 0.002s
2025-10-16 11:00:31,608 - alphagenome_ui - INFO - start:49 - Starting new chat session
2025-10-16 11:00:31,609 - alphagenome_ui - ERROR - handle_unexpected_error:133 - Unexpected error during session initialization: Traceback (most recent call last):
  File "/workspaces/alphagenome/app.py", line 77, in start
    await MessageEnhancements.send_enhanced_message(
  File "/workspaces/alphagenome/ui_enhancements.py", line 334, in send_enhanced_message
    avatar_config = cl.Avatar(
                    ^^^^^^^^^
  File "/usr/local/python/3.12.1/lib/python3.12/site-packages/chainlit/utils.py", line 85, in __getattr__
    module_path = registry[name]
                  ~~~~~~~~^^^^^^
KeyError: 'Avatar'

2025-10-16 11:00:31,610 - alphagenome_ui - INFO - end_timer:175 - Performance [session_initialization]: 0.002s
2025-10-16 11:03:15,994 - alphagenome_ui - INFO - setup_logging:245 - AlphaGenome UI logging initialized
2025-10-16 11:04:35,228 - alphagenome_ui - INFO - start:49 - Starting new chat session
2025-10-16 11:04:35,230 - alphagenome_ui - INFO - start:96 - API key found in environment, initializing model
2025-10-16 11:04:35,231 - alphagenome_ui - INFO - initialize_model:110 - Initializing AlphaGenome model
2025-10-16 11:04:35,329 - alphagenome_ui - INFO - initialize_model:136 - DNA client created successfully in 0.10s
2025-10-16 11:04:36,407 - alphagenome_ui - INFO - initialize_model:151 - Metadata retrieved successfully in 1.08s
2025-10-16 11:04:36,407 - alphagenome_ui - INFO - initialize_model:170 - Model initialized with 11 available output types
2025-10-16 11:04:36,408 - alphagenome_ui - INFO - end_timer:175 - Performance [model_initialization]: 1.177s - {'output_types': 11}
2025-10-16 11:04:36,409 - alphagenome_ui - INFO - initialize_model:190 - Model initialization completed successfully
2025-10-16 11:04:36,409 - alphagenome_ui - INFO - end_timer:175 - Performance [session_initialization]: 1.180s
2025-10-16 11:06:43,470 - alphagenome_ui - INFO - setup_logging:245 - AlphaGenome UI logging initialized
